3, 2: error: unexpected `continue` encountered outside of loop
